Workbook

Sheet 3 Statement Model
B2: Drivers | C2: =C49 -> 45291 | D2: =D49 -> 45657 | E2: =E49 -> 46022 | F2: =F49 -> 46387 | G2: =G49 -> 46752 | H2: =H49 -> 47118 | I2: =I49 -> 47483 | J2: =J49 -> 47848 | K2: =K49 -> 48213
B3: For Income statement
B4: CAGR for Revenue | D4: =D52/C53 -1 -> 0.0097834495 | E4: =E52/D53 -1 -> 0.02070106 | F4: =F52/E53 -1 -> 0.030513623 | G4: =AVERAGE(D4:F4) -> 0.020332711 | H4: =G4 -> 0.020332711 | I4: =H4 -> 0.020332711 | J4: =I4 -> 0.020332711 | K4: =J4 -> 0.020332711
B6: Product - COGS % Revenue | C6: =C55/C$53 -> 0.00018508588 | D6: =D55/D$53 -> 0.00036643201 | E6: =E55/E$53 -> 3.9120029e-05 | F6: =F55/F$53 -> 0.00013396146 | G6: =AVERAGE(C6:F6) -> 0.00018114984 | H6: =G6 -> 0.00018114984 | I6: =H6 -> 0.00018114984 | J6: =I6 -> 0.00018114984 | K6: =J6 -> 0.00018114984
B7: Services - COGS % Revenue | C7: =C56/C$53 -> 0.087275109 | D7: =D56/D$53 -> 0.100548 | E7: =E56/E$53 -> 0.094171116 | F7: =F56/F$53 -> 0.093214852 | G7: =AVERAGE(C7:F7) -> 0.09380227 | H7: =G7 -> 0.09380227 | I7: =H7 -> 0.09380227 | J7: =I7 -> 0.09380227 | K7: =J7 -> 0.09380227
B8: Opex % Revenue | C8: =C57/C$53 -> 0.4489685 | D8: =D57/D$53 -> 0.42669128 | E8: =E57/E$53 -> 0.41956692 | F8: =F57/F$53 -> 0.40887271 | G8: =AVERAGE(C8:F8) -> 0.42602485 | H8: =G8 -> 0.42602485 | I8: =H8 -> 0.42602485 | J8: =I8 -> 0.42602485 | K8: =J8 -> 0.42602485
B9: Effective finance cost rate | F9: =F68/AVERAGE(E99+E97,F99+F97) -> 0.10097316 | G9: =F9 -> 0.10097316 | H9: =G9 -> 0.10097316 | I9: =H9 -> 0.10097316 | J9: =I9 -> 0.10097316 | K9: =J9 -> 0.10097316
B10: Tax Rate -. Assumption | G10: 0.3 | H10: 0.3 | I10: 0.3 | J10: 0.3 | K10: 0.3
B11: Re-measurement gain / (loss) on defined benefit plans | C11: =-C74/C73 -> 0.00039247673 | D11: =-D74/D73 -> -0.0003009117 | E11: =-E74/E73 -> -0.00062812465 | F11: =-F74/F73 -> -0.00034730262 | G11: =-AVERAGE(C11:F11) -> 0.00022096556 | H11: =G11 -> 0.00022096556 | I11: =H11 -> 0.00022096556 | J11: =I11 -> 0.00022096556 | K11: =J11 -> 0.00022096556
B13: Component
B14: Interest income | C14: 247.1 | D14: 43.3 | E14: 970.3 | F14: 506
B15: Gain on mutual funds (including fair value gain/loss) | C15: 29 | D15: 23.9 | E15: 19.2 | F15: 35
B16: Profit on sale of equity instruments | C16: 0 | D16: 0 | E16: 1.3 | F16: 0
B17: Others | C17: 35.2 | D17: 46 | E17: 29.8 | F17: 0
B18: Total other income | C18: =SUM(C14:C17) -> 311.3 | D18: =SUM(D14:D17) -> 113.2 | E18: =SUM(E14:E17) -> 1020.6 | F18: =SUM(F14:F17) -> 541 | G18: =AVERAGE(C18:F18) -> 496.525
B20: For Balance Sheet
B21: Accounts Receivable % Revenue: | D21: =D85/D53 -> 0.051554165 | E21: =E85/E53 -> 0.046030468 | F21: =F85/F53 -> 0.043961687 | G21: =AVERAGE(C21:F21) -> 0.047182107 | H21: =G21 -> 0.047182107 | I21: =H21 -> 0.047182107 | J21: =I21 -> 0.047182107 | K21: =J21 -> 0.047182107
B22: Inventory & Others % COGS: | D22: =D86/SUM(D55:D56) -> 0.00027931661 | E22: =E86/SUM(E55:E56) -> 0.00026868588 | F22: =F86/SUM(F55:F56) -> 0.0050227218 | G22: =AVERAGE(C22:F22) -> 0.0018569081 | H22: =G22 -> 0.0018569081 | I22: =H22 -> 0.0018569081 | J22: =I22 -> 0.0018569081 | K22: =J22 -> 0.0018569081
B23: Other Assets % Op.Ex: | D23: =D91/D57 -> 1.3147027 | E23: =E91/E57 -> 1.4124787 | F23: =F91/F57 -> 1.3882488 | G23: =AVERAGE(C23:F23) -> 1.37181 | H23: =G23 -> 1.37181 | I23: =H23 -> 1.37181 | J23: =I23 -> 1.37181 | K23: =J23 -> 1.37181
B25: Accounts Payable % COGS: | D25: =D96/SUM(D55:D56) -> 3.2136772 | E25: =E96/SUM(E55:E56) -> 2.625403 | F25: =F96/SUM(F55:F56) -> 2.1109782 | G25: =AVERAGE(C25:F25) -> 2.6500195 | H25: =G25 -> 2.6500195 | I25: =H25 -> 2.6500195 | J25: =I25 -> 2.6500195 | K25: =J25 -> 2.6500195
B26: Lease Liabilities % Op.Ex: | D26: =D97/D57 -> 1.9916545 | E26: =E97/E57 -> 2.0256188 | F26: =F97/F57 -> 2.352045 | G26: =AVERAGE(C26:F26) -> 2.1231061 | H26: =G26 -> 2.1231061 | I26: =H26 -> 2.1231061 | J26: =I26 -> 2.1231061 | K26: =J26 -> 2.1231061
B27: Other Liabilities % Total Expenses: | D27: =D101/SUM(D55:D57) -> 1.3784859 | E27: =E101/SUM(E55:E57) -> 1.068483 | F27: =F101/SUM(F55:F57) -> 1.1427047 | G27: =AVERAGE(C27:F27) -> 1.1965579 | H27: =G27 -> 1.1965579 | I27: =H27 -> 1.1965579 | J27: =I27 -> 1.1965579 | K27: =J27 -> 1.1965579
B29: Equity
B30: As per the Fy 25-27 report that the VI company is planning to raise Equity worth of ₹45000 cr in Fy 27-29, So lets assume that it will equally for the forecasting years | G30: 0 | H30: 0 | I30: 0 | J30: 0 | K30: 0
B32: For Cashflow
B33: CapEx % Revenue | C33: =-C126/C53 -> 0.13340895 | D33: =-D126/D53 -> 0.03790927 | E33: =-E126/E53 -> 0.23786128 | F33: =-F126/F53 -> 0.24512715 | G33: =-15000/G53 -> -0.32822986 | H33: =-15000/H53 -> -0.32168905 | I33: =-15000/I53 -> -0.31527858 | J33: =I33 -> -0.31527858 | K33: =J33 -> -0.31527858
B34: Depreciation % Revenue | C34: =C118/C53 -> 0.33833698 | D34: =D118/D53 -> 0.32583087 | E34: =E118/E53 -> 0.30821291 | F34: =F118/F53 -> 0.29415705 | G34: =AVERAGE(C34:F34) -> 0.31663445 | H34: =G34 -> 0.31663445 | I34: =H34 -> 0.31663445 | J34: =I34 -> 0.31663445 | K34: =J34 -> 0.31663445
B35: Amortization % Revenue | C35: =C119/C53 -> 0.20860839 | D35: =D119/D53 -> 0.20581265 | E35: =E119/E53 -> 0.19742958 | F35: =F119/F53 -> 0.19944629 | G35: =AVERAGE(C35:F35) -> 0.20282423 | H35: =G35 -> 0.20282423 | I35: =H35 -> 0.20282423 | J35: =I35 -> 0.20282423 | K35: =J35 -> 0.20282423
B36: Pensions / Other Items: | C36: =C120/C53 -> 0.54918776 | D36: =D120/D53 -> 0.58698415 | E36: =E120/E53 -> 0.53997377 | F36: =F120/F53 -> -0.83964813 | G36: =AVERAGE(C36:F36) -> 0.20912439 | H36: =G36 -> 0.20912439 | I36: =H36 -> 0.20912439 | J36: =I36 -> 0.20912439 | K36: =J36 -> 0.20912439
B38: Acquisitions & Other: | C38: =C127 | D38: =D127 -> -292.9 | E38: =E127 -> -5911.8 | F38: =F127 -> 4875 | G38: =F38 -> 4875 | H38: =G38 -> 4875 | I38: =H38 -> 4875 | J38: =I38 -> 4875 | K38: =J38 -> 4875
B40: New funding required: | G40: =MAX(0,G42-(F84+G123+G128+G131-G68)) -> 8272.4132 | H40: =MAX(0,H42-(G84+H123+H128+H131-H68)) -> 15537.98 | I40: =MAX(0,I42-(H84+I123+I128+I131-I68)) -> 13675.077 | J40: =MAX(0,J42-(I84+J123+J128+J131-J68)) -> 14592.968 | K40: =MAX(0,K42-(J84+K123+K128+K131-K68)) -> 15931.136
B41: Common Dividends % Net Income | C41: =C132/C75 -> 0 | D41: =D132/D75 -> -3.2002253e-06 | E41: =E132/E75 -> -3.6495951e-06 | F41: =F132/F75 -> 0
B42: Minimum year-end cash: | G42: 2000 | H42: 2000 | I42: 2000 | J42: 2000 | K42: 2000
G48: FORECAST
B49: Income Statement: | C49: 45291 | D49: =EOMONTH(C49,12) -> 45657 | E49: =EOMONTH(D49,12) -> 46022 | F49: =EOMONTH(E49,12) -> 46387 | G49: =EOMONTH(F49,12) -> 46752 | H49: =EOMONTH(G49,12) -> 47118 | I49: =EOMONTH(H49,12) -> 47483 | J49: =EOMONTH(I49,12) -> 47848 | K49: =EOMONTH(J49,12) -> 48213
B51: Products: | C51: 8.7 | D51: 17.8 | E51: 2 | F51: 7
B52: Services: | C52: 42133.9 | D52: 42554.9 | E52: 43454 | F52: 44782
B53: Total Income: | C53: =SUM(C51:C52) -> 42142.6 | D53: =SUM(D51:D52) -> 42572.7 | E53: =SUM(E51:E52) -> 43456 | F53: =SUM(F51:F52) -> 44789 | G53: =F53*(1+G4) -> 45699.682 | H53: =G53*(1+H4) -> 46628.88 | I53: =H53*(1+I4) -> 47576.972 | J53: =I53*(1+J4) -> 48544.341 | K53: =J53*(1+K4) -> 49531.379
B55: Cost of Products: | C55: 7.8 | D55: 15.6 | E55: 1.7 | F55: 6 | G55: =G$53*G6 -> 8.2784902 | H55: =H$53*H6 -> 8.4468144 | I55: =I$53*I6 -> 8.618561 | J55: =J$53*J6 -> 8.7937997 | K55: =K$53*K6 -> 8.9726015
B56: Cost of Services: | C56: 3678 | D56: 4280.6 | E56: 4092.3 | F56: 4175 | G56: =G$53*G7 -> 4286.7339 | H56: =H$53*H7 -> 4373.8948 | I56: =I$53*I7 -> 4462.8279 | J56: =J$53*J7 -> 4553.5693 | K56: =K$53*K7 -> 4646.1557
...

Sheet Notes
A1: Vodafone Idea Limited - Consolidated Financial Statements, FY2021-22 to FY2025-26
A2: Five financial years (each ending March 31) side by side. Every figure is typed from the company's annual reports; nothing is estimated.
A4: Sources (each year is taken from its own annual report, i.e. as originally reported)
A5: FY2025-26: Annual Report 2025-26 (reported in ₹ Crore). FY2024-25: Annual Report 2024-25. FY2023-24: Annual Report 2023-24. FY2022-23: Annual Report 2022-23. (these three in ₹ Mn).
A6: FY2021-22: the 2021-22 annual report was not provided, so this column is the comparative-year column printed in the 2022-23 annual report. It may differ slightly from the original 2021-22 report if anything was regrouped.
A8: Unit
A9: All sheets are in ₹ Crore. The 2022-23, 2023-24 and 2024-25 reports (and so FY2021-22 to FY2024-25) are printed in ₹ Mn; those figures are divided by 10 (1 Crore = 10 Mn), which is exact to one decimal. The 2025-26 report is printed in whole ₹ Crore. To get the original ₹ Mn number for the older years, multiply by 10.
A10: EPS is in ₹ per share and share counts are numbers of shares; neither is converted.
A12: Sheets
A13: Balance Sheet, Profit and Loss, Cash Flows: one column per year, all years on one page.
A14: Changes in Equity: share capital roll-forward and other-equity blocks for each year, stacked on one page (a reserve-by-reserve table cannot sit in year columns).
A15: Financing Liabilities: the disclosure table printed after the cash flow statement (changes in borrowings, deferred payment obligations, interest accrued and lease liabilities), stacked by year.
... A26: Because of the whole-crore rounding in the 2025-26 report, FY2024-25 figures here (from the 2024-25 report, divided by 10) can differ by up to about one crore from that report's comparative column.

Sheet Balance Sheet
A1: Vodafone Idea Limited
A2: CONSOLIDATED BALANCE SHEET
A3: ₹ Crore (FY2021-22 to FY2024-25 reports are in ₹ Mn and are shown here divided by 10; FY2025-26 report is in ₹ Crore)
A5: Particulars | B5: FY2021-22 As at Mar 31, 2022 | C5: FY2022-23 As at Mar 31, 2023 | D5: FY2023-24 As at Mar 31, 2024 | E5: FY2024-25 As at Mar 31, 2025 | F5: FY2025-26 As at Mar 31, 2026
A6: Source | B6: Comparative in AR 2022-23 | C6: AR 2022-23 | D6: AR 2023-24 | E6: AR 2024-25 | F6: AR 2025-26
A7: Unit in the source report | B7: ₹ Mn | C7: ₹ Mn | D7: ₹ Mn | E7: ₹ Mn | F7: ₹ Crore
A8: ASSETS
A9: Non-current assets
A10: Property, plant and equipment (including RoU Assets) | B10: 53632.7 | C10: 59821.1 | D10: 52176 | E10: 56195.6 | F10: 64240 | H10: =C10+C11+C12+C13 -> 174131.6 | I10: =D10+D11+D12+D13 -> 158313.9 | J10: =E10+E11+E12+E13 -> 159531.8 | K10: =F10+F11+F12+F13 -> 158360 | L10: <- Fixed Assets
A11: Capital work-in-progress | B11: 323.9 | C11: 300.3 | D11: 638.8 | E11: 2471.6 | F11: 1454
A12: Intangible assets | B12: 103185.9 | C12: 96434.1 | D12: 87948.8 | E12: 85124 | F12: 78846
A13: Intangible assets under development | B13: 40.4 | C13: 17576.1 | D13: 17550.3 | E13: 15740.6 | F13: 13820
A14: Investments accounted for using the equity method | B14: 5.3 | C14: 5.8 | D14: 0.3 | E14: 0 | F14: 0 | H14: =C14+C23 -> 5.8 | I14: =D14+D23 -> 0.5 | J14: =E14+E23 -> 0 | K14: =F14+F23 -> 107 | L14: <-Investments
A15: Financial assets
A16: Other non-current financial assets | B16: 8849.2 | C16: 8850.1 | D16: 7100.2 | E16: 728 | F16: 3356 | H16: =C16+C18+C29+C27 -> 30006.8 | I16: =D16+D18+D29+D27 -> 23882.1 | J16: =E16+E18+E29+E27 -> 25753.3 | K16: =F16+F18+F29+F27 -> 25423 | L16: <- Other Assets
A17: Deferred tax assets (net) | B17: 6 | C17: 13.5 | D17: 13.8 | E17: 11.6 | F17: 17 | H17: =C17+C28 -> 13.5 | I17: =D17+D28 -> 19.7 | J17: =E17+E28 -> 11.6 | K17: =F17+F28 -> 27 | L17: <- Tax assets
A18: Other non-current assets | B18: 11150.2 | C18: 10338.8 | D18: 6659.7 | E18: 6555.7 | F18: 8029
A19: Total non-current assets (A) | B19: 177193.6 | C19: 193339.8 | D19: 172087.9 | E19: 166827.1 | F19: 169762
A20: Current assets
A21: Inventories | B21: 2.3 | C21: 16.3 | D21: 1.2 | E21: 1.1 | F21: 21 | H21: =C21 -> 16.3 | I21: =D21 -> 1.2 | J21: =E21 -> 1.1 | K21: =F21 -> 21 | L21: <- Inventory
A22: Financial assets
A23: Current investments | D23: 0.2 | E23: 0 | F23: 107
A24: Trade receivables | B24: 2443.9 | C24: 2164 | D24: 2194.8 | E24: 2000.3 | F24: 1969 | H24: =C24 -> 2164 | I24: =D24 -> 2194.8 | J24: =E24 -> 2000.3 | K24: =F24 -> 1969 | L24: <-accounts receivables
A25: Cash and cash equivalents | B25: 1453.2 | C25: 228.8 | D25: 167.8 | E25: 256.8 | F25: 2106 | H25: =C25+C26 -> 855.4 | I25: =D25+D26 -> 536.2 | J25: =E25+E26 -> 10568.5 | K25: =F25+F26 -> 5731 | L25: <-Cash & Bank
A26: Bank balance other than cash and cash equivalents | B26: 2043.4 | C26: 626.6 | D26: 368.4 | E26: 10311.7 | F26: 3625
A27: Other current financial assets | B27: 75.6 | C27: 39.4 | D27: 53.4 | E27: 6926.2 | F27: 2131 | H27: =B25 -> 1453.2 | I27: =C25 -> 228.8 | J27: =D25 -> 167.8 | K27: =E25 -> 256.8 | L27: =F25 -> 2106 | M27: <- Cash Changes
A28: Current tax assets | B28: 603.1 | C28: 0 | D28: 5.9 | E28: 0 | F28: 10
A29: Other current assets | B29: 10214 | C29: 10778.5 | D29: 10068.8 | E29: 11543.4 | F29: 11907
A30: Total current assets (B) | B30: 16835.5 | C30: 13853.6 | D30: 12860.5 | E30: 31039.5 | F30: 21876
A31: Assets classified as held for sale (AHFS) (C) | B31: - | C31: 49.3 | D31: 49.3 | E31: 0 | F31: 0 | H31: =C31 -> 49.3 | I31: =D31 -> 49.3 | J31: =E31 -> 0 | K31: =F31 -> 0 | L31: <- Assets which are sale
A32: Total Assets (A+B+C) | B32: 194029.1 | C32: 207242.7 | D32: 184997.7 | E32: 197866.6 | F32: 191638
A34: EQUITY AND LIABILITIES | I34: =C32-'[1]Financial Statements'!$C$92 -> 0
A35: Equity
A36: Equity share capital | B36: 32118.8 | C36: 48679.7 | D36: 50119.8 | E36: 71393 | F36: 108343
A37: Other equity | B37: -94083.6 | C37: -123038.8 | D37: -154286.6 | E37: -141713.2 | F37: -144101
A38: Total equity (A) | B38: -61964.8 | C38: -74359.1 | D38: -104166.8 | E38: -70320.2 | F38: -35758
A39: Liabilities
A40: Non-current liabilities
A41: Financial liabilities
A42: Long term borrowings
...

Sheet Profit and Loss
A1: Vodafone Idea Limited
A2: CONSOLIDATED STATEMENT OF PROFIT AND LOSS
A3: ₹ Crore (FY2021-22 to FY2024-25 reports are in ₹ Mn and are shown here divided by 10; FY2025-26 report is in ₹ Crore)
A5: Particulars | B5: FY2021-22 Year ended Mar 31, 2022 | C5: FY2022-23 Year ended Mar 31, 2023 | D5: FY2023-24 Year ended Mar 31, 2024 | E5: FY2024-25 Year ended Mar 31, 2025 | F5: FY2025-26 Year ended Mar 31, 2026
A6: Source | B6: Comparative in AR 2022-23 | C6: AR 2022-23 | D6: AR 2023-24 | E6: AR 2024-25 | F6: AR 2025-26
A7: Unit in the source report | B7: ₹ Mn | C7: ₹ Mn | D7: ₹ Mn | E7: ₹ Mn | F7: ₹ Crore
A8: INCOME
A9: Service revenue | B9: 38489.5 | C9: 42133.9 | D9: 42554.9 | E9: 43453.7 | F9: 44782
A10: Sale of trading goods | B10: 8.9 | C10: 8.7 | D10: 17.8 | E10: 2 | F10: 7
A11: Other operating income | B11: 17.1 | C11: 34.6 | D11: 79 | E11: 115.6 | F11: 84
A12: Revenue from operations | B12: 38515.5 | C12: 42177.2 | D12: 42651.7 | E12: 43571.3 | F12: 44873 | H12: =C11+C13+C30+C32 -> 324 | I12: =D11+D13+D30+D32 -> 942.2 | J12: =E11+E13+E30+E32 -> 1138 | K12: =F11+F13+F30+F32 -> 59232 | L12: <- other income
A13: Other income | B13: 129.4 | C13: 311.3 | D13: 113.2 | E13: 1020.6 | F13: 541 | H13: =C23 -> 887.4 | I13: =D23 -> 941.7 | J13: =E23 -> 887.1 | K13: =F23 -> 1039 | L13: <- other expense
A14: Total income | B14: 38644.9 | C14: 42488.5 | D14: 42764.9 | E14: 44591.9 | F14: 45414
A15: EXPENSES
A16: Cost of trading goods | B16: 7 | C16: 7.8 | D16: 15.6 | E16: 1.7 | F16: 6
A17: Employee benefit expenses | B17: 1735.1 | C17: 1866.3 | D17: 2122.4 | E17: 2230.9 | F17: 2337 | H17: =C18+C19+C20+C22 -> 18920.7 | I17: =D18+D19+D20+D22 -> 18165.4 | J17: =E18+E19+E20+E22 -> 18232.7 | K17: =F18+F19+F20+F22 -> 18313 | L17: <- operating expenses
A18: Network expenses and IT outsourcing cost | B18: 9818.2 | C18: 10078.3 | D18: 9810.4 | E18: 9439.1 | F18: 9418
A19: License fees and spectrum usage charges | B19: 4198.8 | C19: 4002.1 | D19: 3672.6 | E19: 3696.2 | F19: 3851
A20: Roaming and access charges | B20: 2915.5 | C20: 3899.1 | D20: 4117.7 | E20: 4597.4 | F20: 4501
A21: Subscriber acquisition and servicing expenditure | B21: 1971.1 | C21: 3678 | D21: 4280.6 | E21: 4092.3 | F21: 4175
A22: Advertisement, business promotion expenditure and content cost | B22: 979.1 | C22: 941.2 | D22: 564.7 | E22: 500 | F22: 543
A23: Other expenses | B23: 854.6 | C23: 887.4 | D23: 941.7 | E23: 887.1 | F23: 1039
A24: Total expenses before finance costs, depreciation and amortisation (sub-total, unlabelled in the reports) | B24: 22479.4 | C24: 25360.2 | D24: 25525.7 | E24: 25444.7 | F24: 25870
A25: Profit / (Loss) before finance costs, depreciation, amortisation, share of profit / (loss) of joint venture and associates, exceptional items and tax | B25: 16165.5 | C25: 17128.3 | D25: 17239.2 | E25: 19147.2 | F25: 19544
A26: Finance costs | B26: 20980.8 | C26: 23354.3 | D26: 25765.5 | E26: 24543.4 | F26: 21495
A27: Depreciation | B27: 14656.9 | C27: 14258.4 | D27: 13871.5 | E27: 13393.7 | F27: 13175
A28: Amortisation | B28: 8927.4 | C28: 8791.3 | D28: 8762 | E28: 8579.5 | F28: 8933
A29: Profit / (Loss) before share of profit / (loss) of joint venture and associates, exceptional items and tax | B29: -28399.6 | C29: -29275.7 | D29: -31159.8 | E29: -27369.4 | F29: -24059
... A33: Profit / (Loss) before tax | B33: -28234.1 | C33: -29297.6 | D33: -30409.8 | E33: -27367.6 | F33: 34548
A34: Tax expense:
A35: - Current tax | B35: 17.3 | C35: 11.5 | D35: 828.5 | E35: -2.7 | F35: 11
A36: - Deferred tax | B36: -6 | C36: -8 | D36: 0.1 | E36: 18.5 | F36: -15 | H36: =C35+C36 -> 3.5 | I36: =D35+D36 -> 828.6 | J36: =E35+E36 -> 15.8 | K36: =F35+F36 -> -4 | L36: <- Tax
A37: Profit / (Loss) after tax for the year | B37: -28245.4 | C37: -29301.1 | D37: -31238.4 | E37: -27383.4 | F37: 34552
A39: OTHER COMPREHENSIVE INCOME / (LOSS)
A40: Items that will not be reclassified to profit or loss:
A41: Re-measurement gain / (loss) on defined benefit plans | B41: 9 | C41: 11.5 | D41: -9.4 | E41: -17.2 | F41: 12
A42: Income tax effect | B42: -0.1 | C42: -0.4 | D42: - | E42: -* | F42: -*
A43: Other comprehensive income / (loss) for the year, net of tax | B43: 8.9 | C43: 11.1 | D43: -9.4 | E43: -17.2 | F43: 12
A44: Total comprehensive income / (loss) for the year | B44: -28236.5 | C44: -29290 | D44: -31247.8 | E44: -27400.6 | F44: 34564
A46: Earnings / (loss) per equity share of ₹ 10 each (in ₹, not converted):
...

Sheet Cash Flows
A1: Vodafone Idea Limited
A2: CONSOLIDATED STATEMENT OF CASH FLOWS
A3: ₹ Crore (FY2021-22 to FY2024-25 reports are in ₹ Mn and are shown here divided by 10; FY2025-26 report is in ₹ Crore)
A5: Particulars | B5: FY2021-22 Year ended Mar 31, 2022 | C5: FY2022-23 Year ended Mar 31, 2023 | D5: FY2023-24 Year ended Mar 31, 2024 | E5: FY2024-25 Year ended Mar 31, 2025 | F5: FY2025-26 Year ended Mar 31, 2026
A6: Source | B6: Comparative in AR 2022-23 | C6: AR 2022-23 | D6: AR 2023-24 | E6: AR 2024-25 | F6: AR 2025-26
A7: Unit in the source report | B7: ₹ Mn | C7: ₹ Mn | D7: ₹ Mn | E7: ₹ Mn | F7: ₹ Crore
A8: OPERATING ACTIVITIES
A9: Profit / (Loss) before tax | B9: -28234.1 | C9: -29297.6 | D9: -30409.8 | E9: -27367.6 | F9: 34548
A10: Adjustments to reconcile profit / (loss) before tax to net cash flows
A11: Share of (profit) / loss of joint venture and associates, net of tax | B11: -1.2 | C11: -0.5 | D11: 5.5 | E11: -1.8 | F11: 0
A12: Depreciation of property, plant and equipment (including RoU Assets) | B12: 14656.9 | C12: 14258.4 | D12: 13871.5 | E12: 13393.7 | F12: 13175 | H12: =C12+C13 -> 23049.7 | I12: =D12+D13 -> 22633.5 | J12: =E12+E13 -> 21973.2 | K12: =F12+F13 -> 22108 | L12: <- Depreciation
A13: Amortisation of intangible assets | B13: 8927.4 | C13: 8791.3 | D13: 8762 | E13: 8579.5 | F13: 8933 | H13: =SUM(C14:C27,C11) -> 23144.2 | I13: =SUM(D14:D27,D11) -> 24989.5 | J13: =SUM(E14:E27,E11) -> 23465.1 | K13: =SUM(F14:F27,F11) -> -37607 | L13: <- pension & Other items
A14: Share-based payment expense (ESOS) | B14: -1.6 | C14: 0.2 | D14: -
A15: Gain on disposal of property, plant and equipment and intangible assets (net) | B15: -67.9 | C15: -64.2 | D15: -48.6 | E15: -77.9 | F15: -144
A16: Loss / (Gain) on leasehold land | B16: -126.6 | C16: 22.4 | D16: -
A17: Accelerated depreciation on account of network re-alignment / re-farming | B17: 13.7 | C17: -
A18: Differential entry fees impact / Gain arising out of the TDSAT ruling accepted by DoT | D18: -755.5 | E18: -
A19: Exceptional items (net) | F19: -58607
A20: Finance costs | B20: 20980.8 | C20: 23354.3 | D20: 25765.5 | E20: 24543.4 | F20: 21495
A21: Bad debts / advances written off | B21: 175.6 | C21: 117 | D21: 211.9 | E21: 152.8 | F21: 126
A22: Allowance for doubtful debts / advances | B22: 47.9 | C22: 8.6 | D22: -47.8 | E22: -49.9 | F22: 108
A23: Liabilities / provisions no longer required written back | B23: -7 | C23: -17.5 | D23: -74.3 | E23: -110.7 | F23: -44
A24: Other income (single line in the FY2021-22 and FY2022-23 presentation) | B24: -105.7 | C24: -276.1
A25: Interest income | D25: -43.3 | E25: -970.3 | F25: -506
A26: Gain on Mutual Funds (including fair value gain / (loss)) | D26: -23.9 | E26: -19.2 | F26: -35
A27: Profit on sale of Equity Instruments | E27: -1.3 | F27: -
A28: Working capital adjustments
A29: (Increase) / Decrease in trade receivables | B29: -38.3 | C29: 184.7 | D29: -170.7 | E29: 103.5 | F29: -162 | H29: =SUM(C29:C33) -> 627.5 | I29: =SUM(D29:D33) -> 642.5 | J29: =SUM(E29:E33) -> -9255.6 | K29: =SUM(F29:F33) -> -47 | L29: <- Change in working capital
A30: (Increase) / Decrease in inventories | B30: -1.7 | C30: -14 | D30: 15.1 | E30: 0.1 | F30: -20
A31: Decrease / (Increase) in other financial and non-financial assets | B31: -3005.1 | C31: 1062.6 | D31: 1117.4 | E31: -5081.8 | F31: 1847
A32: (Decrease) in trade payables | B32: -343.2 | C32: -247.7 | D32: -1012.8 | E32: -3440 | F32: -979 | I32: =C34-'[1]Financial Statements'!C123 -> -1344.9 | J32: =D34-'[1]Financial Statements'!D123 -> -2970.4 | K32: =E34-'[1]Financial Statements'!E123 -> -475.8 | L32: =F34-'[1]Financial Statements'!F123 -> -409
A33: Increase / (Decrease) in other financial and non-financial liabilities | B33: 3047.6 | C33: -358.1 | D33: 693.5 | E33: -837.4 | F33: -733
A34: Cash flows from operating activities | B34: 15917.5 | C34: 17523.8 | D34: 17855.7 | E34: 8815.1 | F34: 19002
A35: Income tax refund (including TDS) (net) | B35: 1469.5 | C35: 1344.9 | D35: 2970.4 | E35: 475.5 | F35: 409 | H35: =C35 -> 1344.9 | I35: =D35 -> 2970.4 | J35: =E35 -> 475.5 | K35: =F35 -> 409
A36: Net cash flows from operating activities | B36: 17387 | C36: 18868.7 | D36: 20826.1 | E36: 9290.6 | F36: 19411
A38: INVESTING ACTIVITIES
A39: Purchase of / Payment towards property, plant and equipment and intangible assets (including CWIP and intangible assets under development) | B39: -6008.9 | C39: -3942.2 | D39: -1613.9 | E39: -10005 | F39: -10979 | H39: =C39+C40 -> -5622.2 | I39: =D39+D40 -> -1613.9 | J39: =E39+E40 -> -10336.5 | K39: =F39+F40 -> -10979 | L39: <- Capex
A40: Payment towards Spectrum - Upfront payment | B40: -103.5 | C40: -1680 | D40: 0 | E40: -331.5 | F40: 0 | H40: =SUM(C41:C49) -> 208.6 | I40: =SUM(D41:D49) -> -292.9 | J40: =SUM(E41:E49) -> -5911.8 | K40: =SUM(F41:F49) -> 4875 | L40: <- Others
A41: Payment of Deferred Payment obligation towards Spectrum | D41: -448.3 | E41: -503.7 | F41: -589
A42: Proceeds from sale of property, plant and equipment and intangible assets | B42: 120.7 | C42: 85.7 | D42: 84 | E42: 114.7 | F42: 165
...

Sheet Changes in Equity
A1: Vodafone Idea Limited
A2: CONSOLIDATED STATEMENT OF CHANGES IN EQUITY, FY2021-22 to FY2025-26
A3: ₹ Crore (reports up to FY2024-25 are in ₹ Mn and are shown divided by 10; FY2025-26 report is in ₹ Crore). Share counts are numbers of shares.
A5: A. EQUITY SHARE CAPITAL - Equity shares of ₹ 10 each issued, subscribed and fully paid
A6: Particulars | B6: Numbers | C6: Amount (₹ Crore) | D6: Source
A7: As at April 1, 2021 | B7: 28735389240 | C7: 28735.4 | D7: AR 2022-23
A8: Issue of Share capital (Preferential allotment) | B8: 3383458645 | C8: 3383.4 | D8: AR 2022-23
A9: As at March 31, 2022 | B9: 32118847885 | C9: 32118.8 | D9: AR 2022-23
A10: Issue of Share capital | B10: 16560841320 | C10: 16560.9 | D10: AR 2022-23
A11: As at March 31, 2023 | B11: 48679689205 | C11: 48679.7 | D11: AR 2022-23
A12: Issue of Share capital (conversion of OCDs) | B12: 1440000000 | C12: 1440 | D12: AR 2023-24
A13: Issue of shares under Employee Stock Option Scheme (ESOS) | B13: 131170 | C13: 0.1 | D13: AR 2023-24
A14: As at March 31, 2024 | B14: 50119820375 | C14: 50119.8 | D14: AR 2023-24
A15: Issue of share capital through Further Public Offer (FPO) | B15: 16363636363 | C15: 16363.6 | D15: AR 2024-25
A16: Issue of share capital through Conversion of OCDs | B16: 160000000 | C16: 160 | D16: AR 2024-25
A17: Issue of shares under Employee Stock Option Scheme (ESOS) | B17: 122064 | C17: 0.1 | D17: AR 2024-25
A18: Issue of share capital through preferential allotment | B18: 4749456199 | C18: 4749.5 | D18: AR 2024-25
... A21: As at March 31, 2026 | B21: 108343035001 | C21: 108343 | D21: AR 2025-26
A23: B. OTHER EQUITY (₹ Crore) - each year's block as printed in its own report
B24: Reserves and surplus
A25: Particulars | B25: Capital reserve | C25: Capital reduction reserve | D25: Debenture redemption reserve | E25: Securities premium | F25: Amalgamation adjustment deficit account | G25: General reserve | H25: Retained earnings | I25: Employee stock options reserve | J25: Convertible share warrants / Share application amount pending allotment | K25: Total
A26: FY2021-22 (AR 2022-23, ₹ Mn shown as ₹ Crore)
A27: As at April 1, 2021 | B27: -8846 | C27: 27778.7 | D27: 440.8 | E27: 108469.8 | F27: -48844.4 | G27: 156.2 | H27: -146154.6 | I27: 36.1 | J27: - | K27: -66963.4
A28: Profit / (Loss) for the year ended March 31, 2022 | B28: - | C28: - | D28: - | E28: - | F28: - | G28: - | H28: -28245.4 | I28: - | J28: - | K28: -28245.4
A29: Other comprehensive income / (loss) for the year ended March 31, 2022 | B29: - | C29: - | D29: - | E29: - | F29: - | G29: - | H29: 8.9 | I29: - | J29: - | K29: 8.9
A30: Total comprehensive income / (loss) | B30: - | C30: - | D30: - | E30: - | F30: - | G30: - | H30: -28236.5 | I30: - | J30: - | K30: -28236.5
A31: Allotment of Equity Share Capital (net of issue expense of ₹ 3 Mn) | B31: - | C31: - | D31: - | E31: 1116.3 | F31: - | G31: - | H31: - | I31: - | J31: - | K31: 1116.3
A32: Share-based payment expenses | B32: - | C32: - | D32: - | E32: - | F32: - | G32: - | H32: 31.1 | I32: -31.1 | J32: - | K32: -
A33: As at March 31, 2022 | B33: -8846 | C33: 27778.7 | D33: 440.8 | E33: 109586.1 | F33: -48844.4 | G33: 156.2 | H33: -174360 | I33: 5 | J33: - | K33: -94083.6
A34: FY2022-23 (AR 2022-23)
A35: Profit / (Loss) for the year ended March 31, 2023 | B35: - | C35: - | D35: - | E35: - | F35: - | G35: - | H35: -29301.1 | I35: - | J35: - | K35: -29301.1
A36: Other comprehensive income / (loss) for the year ended March 31, 2023 | B36: - | C36: - | D36: - | E36: - | F36: - | G36: - | H36: 11.1 | I36: - | J36: - | K36: 11.1
A37: Total comprehensive income / (loss) | B37: - | C37: - | D37: - | E37: - | F37: - | G37: - | H37: -29290 | I37: - | J37: - | K37: -29290
A38: Adjustment on account of settlement of financial liability | B38: - | C38: - | D38: - | E38: - | F38: - | G38: - | H38: 330.5 | I38: - | J38: - | K38: 330.5
A39: Issue of convertible share warrants | B39: - | C39: - | D39: - | E39: - | F39: - | G39: - | H39: - | I39: - | J39: 436.2 | K39: 436.2
A40: Conversion of convertible share warrants into equity shares (net of share issue expenses of ₹ 42 Mn) | B40: - | C40: - | D40: - | E40: 4.3 | F40: - | G40: - | H40: - | I40: - | J40: -436.2 | K40: -431.9
A41: Share-based payment expenses | B41: - | C41: - | D41: - | E41: - | F41: - | G41: - | H41: 1.2 | I41: -1.2 | J41: - | K41: -
A42: As at March 31, 2023 | B42: -8846 | C42: 27778.7 | D42: 440.8 | E42: 109590.4 | F42: -48844.4 | G42: 156.2 | H42: -203318.3 | I42: 3.8 | J42: - | K42: -123038.8
A43: FY2023-24 (AR 2023-24)
A44: Profit / (Loss) for the year ended March 31, 2024 | B44: - | C44: - | D44: - | E44: - | F44: - | G44: - | H44: -31238.4 | I44: - | J44: - | K44: -31238.4
...

Sheet Financing Liabilities
A1: Vodafone Idea Limited
A2: CONSOLIDATED STATEMENT OF CASH FLOWS - Disclosure of changes in liabilities arising from financing activities (incl. non-cash transactions)
A3: ₹ Crore (reports up to FY2024-25 are in ₹ Mn and are shown divided by 10; FY2025-26 report is in ₹ Crore)
A5: Particulars | B5: Loans from banks and others including current maturities | C5: Deferred payment obligations including current maturities | D5: Changes in derivative liabilities (net) | E5: Interest accrued but not due | F5: Lease liabilities
A6: FY2021-22 (AR 2022-23, ₹ Mn shown as ₹ Crore)
A7: Balance as at April 1, 2021 | B7: 23071.5 | C7: 157238.8 | D7: 44 | E7: 6395.2 | F7: 21409.9
A8: (i) Cash flow items
A9: Net proceed / (repayment) of borrowings | B9: -5308.6 | C9: -5.5 | D9: - | E9: - | F9: -
A10: Payment of Interest and finance charges | B10: - | C10: - | D10: - | E10: -2799.7 | F10: -
A11: Payment of lease liabilities | B11: - | C11: - | D11: - | E11: - | F11: -6939.7
A12: (ii) Non-cash items
A13: Exchange difference (net) | B13: 41.8 | C13: - | D13: - | E13: -41.8 | F13: -
A14: Finance cost (charged to profit and loss) | B14: - | C14: - | D14: -33.8 | E14: 19119 | F14: 1895.6
A15: Upfront fees amortisation | B15: -2.1 | C15: - | D15: - | E15: 2.1 | F15: -
A16: Interest on asset retirement obligation | B16: - | C16: - | D16: - | E16: 0.5 | F16: -
A17: Interest related to other liabilities | B17: - | C17: - | D17: - | E17: -1162 | F17: -
A18: Accrued interest on deferred payment obligation for spectrum and others transferred to borrowing on anniversary date | B18: - | C18: 14566.5 | D18: - | E18: -14566.5 | F18: -
A19: Addition towards Spectrum acquisition | B19: - | C19: 1315.3 | D19: - | E19: 13.7 | F19: -
A20: Addition of lease liabilities | B20: - | C20: - | D20: - | E20: - | F20: 7388.9
A21: Deletion of lease liabilities | B21: - | C21: - | D21: - | E21: - | F21: -911.3
A22: As at March 31, 2022 | B22: 17802.6 | C22: 173115.1 | D22: 10.2 | E22: 6960.5 | F22: 22843.4
A23: FY2022-23 (AR 2022-23)
A24: (i) Cash flow items
A25: Net proceed / (repayment) of borrowings | B25: -5112.9 | C25: -0.7 | D25: - | E25: - | F25: -
A26: Payment of Interest and finance charges | B26: - | C26: - | D26: - | E26: -2094 | F26: -
A27: Payment of lease liabilities | B27: - | C27: - | D27: - | E27: - | F27: -7903.9
A28: (ii) Non-cash items
A29: Exchange difference (net) | B29: 43.5 | C29: - | D29: - | E29: -43.5 | F29: -
A30: Finance cost (charged to profit and loss) | B30: - | C30: - | D30: -9.1 | E30: 19746.1 | F30: 3617.3
A31: Upfront fees amortisation | B31: -4 | C31: - | D31: - | E31: 4 | F31: -
A32: Interest on asset retirement obligation | B32: - | C32: - | D32: - | E32: 0.5 | F32: -
A33: Interest related to other liabilities | B33: - | C33: - | D33: - | E33: -2286 | F33: -
A34: Accrued interest on deferred payment obligation for spectrum and others transferred to borrowing on anniversary date | B34: - | C34: 14769.3 | D34: - | E34: -14769.3 | F34: -
A35: Addition towards Spectrum acquisition | B35: - | C35: 17106.3 | D35: - | E35: 487.6 | F35: -
A36: Issue of equity shares | B36: - | C36: -16133.2 | D36: - | E36: - | F36: -
A37: Adjustment on account of settlement of financial liability | B37: - | C37: - | D37: - | E37: -330.5 | F37: -
A38: Addition of lease liabilities | B38: - | C38: - | D38: - | E38: - | F38: 18684.4
A39: Deletion of lease liabilities | B39: - | C39: - | D39: - | E39: - | F39: -1061.2
A40: As at March 31, 2023 | B40: 12729.2 | C40: 188856.8 | D40: 1.1 | E40: 7675.4 | F40: 36180
A41: FY2023-24 (AR 2023-24)
...

Sheet Tie-out
A1: Vodafone Idea Limited
A2: TIE-OUT: every sub-total re-added from its line items, and cross-checked between statements
A3: Each cell is the difference (recomputed minus reported) in ₹ Crore, rounded to 1 decimal. Nil = ties. Blank = not applicable to that year.
A4: Overall status | B4: =IF(COUNTIF(G8:G65,"CHECK")=0,"All checks passed","Review flagged rows") -> All checks passed
A6: Check | B6: FY2021-22 | C6: FY2022-23 | D6: FY2023-24 | E6: FY2024-25 | F6: FY2025-26 | G6: Status
A7: Balance Sheet
A8: Total non-current assets (A) | B8: =ROUND((SUM('Balance Sheet'!B10:B18))-N('Balance Sheet'!B19),1) -> 0 | C8: =ROUND((SUM('Balance Sheet'!C10:C18))-N('Balance Sheet'!C19),1) -> 0 | D8: =ROUND((SUM('Balance Sheet'!D10:D18))-N('Balance Sheet'!D19),1) -> 0 | E8: =ROUND((SUM('Balance Sheet'!E10:E18))-N('Balance Sheet'!E19),1) -> 0 | F8: =ROUND((SUM('Balance Sheet'!F10:F18))-N('Balance Sheet'!F19),1) -> 0 | G8: =IF(AND(OR(B8="",B8=0),OR(C8="",C8=0),OR(D8="",D8=0),OR(E8="",E8=0),OR(F8="",F8=0)),"OK","CHECK") -> OK
A9: Total current assets (B) | B9: =ROUND((SUM('Balance Sheet'!B21:B29))-N('Balance Sheet'!B30),1) -> 0 | C9: =ROUND((SUM('Balance Sheet'!C21:C29))-N('Balance Sheet'!C30),1) -> 0 | D9: =ROUND((SUM('Balance Sheet'!D21:D29))-N('Balance Sheet'!D30),1) -> 0 | E9: =ROUND((SUM('Balance Sheet'!E21:E29))-N('Balance Sheet'!E30),1) -> 0 | F9: =ROUND((SUM('Balance Sheet'!F21:F29))-N('Balance Sheet'!F30),1) -> 0 | G9: =IF(AND(OR(B9="",B9=0),OR(C9="",C9=0),OR(D9="",D9=0),OR(E9="",E9=0),OR(F9="",F9=0)),"OK","CHECK") -> OK
A10: Total Assets (A+B+C) | B10: =ROUND((N('Balance Sheet'!B19)+N('Balance Sheet'!B30)+N('Balance Sheet'!B31))-N('Balance Sheet'!B32),1) -> 0 | C10: =ROUND((N('Balance Sheet'!C19)+N('Balance Sheet'!C30)+N('Balance Sheet'!C31))-N('Balance Sheet'!C32),1) -> 0 | D10: =ROUND((N('Balance Sheet'!D19)+N('Balance Sheet'!D30)+N('Balance Sheet'!D31))-N('Balance Sheet'!D32),1) -> 0 | E10: =ROUND((N('Balance Sheet'!E19)+N('Balance Sheet'!E30)+N('Balance Sheet'!E31))-N('Balance Sheet'!E32),1) -> 0 | F10: =ROUND((N('Balance Sheet'!F19)+N('Balance Sheet'!F30)+N('Balance Sheet'!F31))-N('Balance Sheet'!F32),1) -> 0 | G10: =IF(AND(OR(B10="",B10=0),OR(C10="",C10=0),OR(D10="",D10=0),OR(E10="",E10=0),OR(F10="",F10=0)),"OK","CHECK") -> OK
A11: Total equity (A) | B11: =ROUND((N('Balance Sheet'!B36)+N('Balance Sheet'!B37))-N('Balance Sheet'!B38),1) -> 0 | C11: =ROUND((N('Balance Sheet'!C36)+N('Balance Sheet'!C37))-N('Balance Sheet'!C38),1) -> 0 | D11: =ROUND((N('Balance Sheet'!D36)+N('Balance Sheet'!D37))-N('Balance Sheet'!D38),1) -> 0 | E11: =ROUND((N('Balance Sheet'!E36)+N('Balance Sheet'!E37))-N('Balance Sheet'!E38),1) -> 0 | F11: =ROUND((N('Balance Sheet'!F36)+N('Balance Sheet'!F37))-N('Balance Sheet'!F38),1) -> 0 | G11: =IF(AND(OR(B11="",B11=0),OR(C11="",C11=0),OR(D11="",D11=0),OR(E11="",E11=0),OR(F11="",F11=0)),"OK","CHECK") -> OK
A12: Total non-current liabilities (B) | B12: =ROUND((SUM('Balance Sheet'!B43:B50))-N('Balance Sheet'!B51),1) -> 0 | C12: =ROUND((SUM('Balance Sheet'!C43:C50))-N('Balance Sheet'!C51),1) -> 0 | D12: =ROUND((SUM('Balance Sheet'!D43:D50))-N('Balance Sheet'!D51),1) -> 0 | E12: =ROUND((SUM('Balance Sheet'!E43:E50))-N('Balance Sheet'!E51),1) -> 0 | F12: =ROUND((SUM('Balance Sheet'!F43:F50))-N('Balance Sheet'!F51),1) -> 0 | G12: =IF(AND(OR(B12="",B12=0),OR(C12="",C12=0),OR(D12="",D12=0),OR(E12="",E12=0),OR(F12="",F12=0)),"OK","CHECK") -> OK
A13: Total current liabilities (C) | B13: =ROUND((SUM('Balance Sheet'!B54:B62))-N('Balance Sheet'!B63),1) -> 0 | C13: =ROUND((SUM('Balance Sheet'!C54:C62))-N('Balance Sheet'!C63),1) -> 0 | D13: =ROUND((SUM('Balance Sheet'!D54:D62))-N('Balance Sheet'!D63),1) -> 0 | E13: =ROUND((SUM('Balance Sheet'!E54:E62))-N('Balance Sheet'!E63),1) -> 0 | F13: =ROUND((SUM('Balance Sheet'!F54:F62))-N('Balance Sheet'!F63),1) -> 0 | G13: =IF(AND(OR(B13="",B13=0),OR(C13="",C13=0),OR(D13="",D13=0),OR(E13="",E13=0),OR(F13="",F13=0)),"OK","CHECK") -> OK
A14: Total Equity and Liabilities (A+B+C) | B14: =ROUND((N('Balance Sheet'!B38)+N('Balance Sheet'!B51)+N('Balance Sheet'!B63))-N('Balance Sheet'!B64),1) -> 0 | C14: =ROUND((N('Balance Sheet'!C38)+N('Balance Sheet'!C51)+N('Balance Sheet'!C63))-N('Balance Sheet'!C64),1) -> 0 | D14: =ROUND((N('Balance Sheet'!D38)+N('Balance Sheet'!D51)+N('Balance Sheet'!D63))-N('Balance Sheet'!D64),1) -> 0 | E14: =ROUND((N('Balance Sheet'!E38)+N('Balance Sheet'!E51)+N('Balance Sheet'!E63))-N('Balance Sheet'!E64),1) -> 0 | F14: =ROUND((N('Balance Sheet'!F38)+N('Balance Sheet'!F51)+N('Balance Sheet'!F63))-N('Balance Sheet'!F64),1) -> 0 | G14: =IF(AND(OR(B14="",B14=0),OR(C14="",C14=0),OR(D14="",D14=0),OR(E14="",E14=0),OR(F14="",F14=0)),"OK","CHECK") -> OK
A15: Balance sheet balances: Total Assets less Total Equity and Liabilities | B15: =ROUND(N('Balance Sheet'!B32)-N('Balance Sheet'!B64),1) -> 0 | C15: =ROUND(N('Balance Sheet'!C32)-N('Balance Sheet'!C64),1) -> 0 | D15: =ROUND(N('Balance Sheet'!D32)-N('Balance Sheet'!D64),1) -> 0 | E15: =ROUND(N('Balance Sheet'!E32)-N('Balance Sheet'!E64),1) -> 0 | F15: =ROUND(N('Balance Sheet'!F32)-N('Balance Sheet'!F64),1) -> 0 | G15: =IF(AND(OR(B15="",B15=0),OR(C15="",C15=0),OR(D15="",D15=0),OR(E15="",E15=0),OR(F15="",F15=0)),"OK","CHECK") -> OK
A16: Statement of Profit and Loss
A17: Revenue from operations | B17: =ROUND((SUM('Profit and Loss'!B9:B11))-N('Profit and Loss'!B12),1) -> 0 | C17: =ROUND((SUM('Profit and Loss'!C9:C11))-N('Profit and Loss'!C12),1) -> 0 | D17: =ROUND((SUM('Profit and Loss'!D9:D11))-N('Profit and Loss'!D12),1) -> 0 | E17: =ROUND((SUM('Profit and Loss'!E9:E11))-N('Profit and Loss'!E12),1) -> 0 | F17: =ROUND((SUM('Profit and Loss'!F9:F11))-N('Profit and Loss'!F12),1) -> 0 | G17: =IF(AND(OR(B17="",B17=0),OR(C17="",C17=0),OR(D17="",D17=0),OR(E17="",E17=0),OR(F17="",F17=0)),"OK","CHECK") -> OK
A18: Total income | B18: =ROUND((N('Profit and Loss'!B12)+N('Profit and Loss'!B13))-N('Profit and Loss'!B14),1) -> 0 | C18: =ROUND((N('Profit and Loss'!C12)+N('Profit and Loss'!C13))-N('Profit and Loss'!C14),1) -> 0 | D18: =ROUND((N('Profit and Loss'!D12)+N('Profit and Loss'!D13))-N('Profit and Loss'!D14),1) -> 0 | E18: =ROUND((N('Profit and Loss'!E12)+N('Profit and Loss'!E13))-N('Profit and Loss'!E14),1) -> 0 | F18: =ROUND((N('Profit and Loss'!F12)+N('Profit and Loss'!F13))-N('Profit and Loss'!F14),1) -> 0 | G18: =IF(AND(OR(B18="",B18=0),OR(C18="",C18=0),OR(D18="",D18=0),OR(E18="",E18=0),OR(F18="",F18=0)),"OK","CHECK") -> OK
A19: Total expenses before finance costs, depreciation and amortisation | B19: =ROUND((SUM('Profit and Loss'!B16:B23))-N('Profit and Loss'!B24),1) -> 0 | C19: =ROUND((SUM('Profit and Loss'!C16:C23))-N('Profit and Loss'!C24),1) -> 0 | D19: =ROUND((SUM('Profit and Loss'!D16:D23))-N('Profit and Loss'!D24),1) -> 0 | E19: =ROUND((SUM('Profit and Loss'!E16:E23))-N('Profit and Loss'!E24),1) -> 0 | F19: =ROUND((SUM('Profit and Loss'!F16:F23))-N('Profit and Loss'!F24),1) -> 0 | G19: =IF(AND(OR(B19="",B19=0),OR(C19="",C19=0),OR(D19="",D19=0),OR(E19="",E19=0),OR(F19="",F19=0)),"OK","CHECK") -> OK
A20: Profit / (Loss) before finance costs, depreciation, amortisation, JV share, exceptional items and tax | B20: =ROUND((N('Profit and Loss'!B14)-N('Profit and Loss'!B24))-N('Profit and Loss'!B25),1) -> 0 | C20: =ROUND((N('Profit and Loss'!C14)-N('Profit and Loss'!C24))-N('Profit and Loss'!C25),1) -> 0 | D20: =ROUND((N('Profit and Loss'!D14)-N('Profit and Loss'!D24))-N('Profit and Loss'!D25),1) -> 0 | E20: =ROUND((N('Profit and Loss'!E14)-N('Profit and Loss'!E24))-N('Profit and Loss'!E25),1) -> 0 | F20: =ROUND((N('Profit and Loss'!F14)-N('Profit and Loss'!F24))-N('Profit and Loss'!F25),1) -> 0 | G20: =IF(AND(OR(B20="",B20=0),OR(C20="",C20=0),OR(D20="",D20=0),OR(E20="",E20=0),OR(F20="",F20=0)),"OK","CHECK") -> OK
A21: Profit / (Loss) before share of JV and associates, exceptional items and tax | B21: =ROUND((N('Profit and Loss'!B25)-SUM('Profit and Loss'!B26:B28))-N('Profit and Loss'!B29),1) -> 0 | C21: =ROUND((N('Profit and Loss'!C25)-SUM('Profit and Loss'!C26:C28))-N('Profit and Loss'!C29),1) -> 0 | D21: =ROUND((N('Profit and Loss'!D25)-SUM('Profit and Loss'!D26:D28))-N('Profit and Loss'!D29),1) -> 0 | E21: =ROUND((N('Profit and Loss'!E25)-SUM('Profit and Loss'!E26:E28))-N('Profit and Loss'!E29),1) -> 0 | F21: =ROUND((N('Profit and Loss'!F25)-SUM('Profit and Loss'!F26:F28))-N('Profit and Loss'!F29),1) -> 0 | G21: =IF(AND(OR(B21="",B21=0),OR(C21="",C21=0),OR(D21="",D21=0),OR(E21="",E21=0),OR(F21="",F21=0)),"OK","CHECK") -> OK
A22: Profit / (Loss) before exceptional items and tax | B22: =ROUND((N('Profit and Loss'!B29)+N('Profit and Loss'!B30))-N('Profit and Loss'!B31),1) -> 0 | C22: =ROUND((N('Profit and Loss'!C29)+N('Profit and Loss'!C30))-N('Profit and Loss'!C31),1) -> 0 | D22: =ROUND((N('Profit and Loss'!D29)+N('Profit and Loss'!D30))-N('Profit and Loss'!D31),1) -> 0 | E22: =ROUND((N('Profit and Loss'!E29)+N('Profit and Loss'!E30))-N('Profit and Loss'!E31),1) -> 0 | F22: =ROUND((N('Profit and Loss'!F29)+N('Profit and Loss'!F30))-N('Profit and Loss'!F31),1) -> 0 | G22: =IF(AND(OR(B22="",B22=0),OR(C22="",C22=0),OR(D22="",D22=0),OR(E22="",E22=0),OR(F22="",F22=0)),"OK","CHECK") -> OK
A23: Profit / (Loss) before tax | B23: =ROUND((N('Profit and Loss'!B31)+N('Profit and Loss'!B32))-N('Profit and Loss'!B33),1) -> 0 | C23: =ROUND((N('Profit and Loss'!C31)+N('Profit and Loss'!C32))-N('Profit and Loss'!C33),1) -> 0 | D23: =ROUND((N('Profit and Loss'!D31)+N('Profit and Loss'!D32))-N('Profit and Loss'!D33),1) -> 0 | E23: =ROUND((N('Profit and Loss'!E31)+N('Profit and Loss'!E32))-N('Profit and Loss'!E33),1) -> 0 | F23: =ROUND((N('Profit and Loss'!F31)+N('Profit and Loss'!F32))-N('Profit and Loss'!F33),1) -> 0 | G23: =IF(AND(OR(B23="",B23=0),OR(C23="",C23=0),OR(D23="",D23=0),OR(E23="",E23=0),OR(F23="",F23=0)),"OK","CHECK") -> OK
A24: Profit / (Loss) after tax for the year | B24: =ROUND((N('Profit and Loss'!B33)-N('Profit and Loss'!B35)-N('Profit and Loss'!B36))-N('Profit and Loss'!B37),1) -> 0 | C24: =ROUND((N('Profit and Loss'!C33)-N('Profit and Loss'!C35)-N('Profit and Loss'!C36))-N('Profit and Loss'!C37),1) -> 0 | D24: =ROUND((N('Profit and Loss'!D33)-N('Profit and Loss'!D35)-N('Profit and Loss'!D36))-N('Profit and Loss'!D37),1) -> 0 | E24: =ROUND((N('Profit and Loss'!E33)-N('Profit and Loss'!E35)-N('Profit and Loss'!E36))-N('Profit and Loss'!E37),1) -> 0 | F24: =ROUND((N('Profit and Loss'!F33)-N('Profit and Loss'!F35)-N('Profit and Loss'!F36))-N('Profit and Loss'!F37),1) -> 0 | G24: =IF(AND(OR(B24="",B24=0),OR(C24="",C24=0),OR(D24="",D24=0),OR(E24="",E24=0),OR(F24="",F24=0)),"OK","CHECK") -> OK
A25: Other comprehensive income / (loss), net of tax | B25: =ROUND((N('Profit and Loss'!B41)+N('Profit and Loss'!B42))-N('Profit and Loss'!B43),1) -> 0 | C25: =ROUND((N('Profit and Loss'!C41)+N('Profit and Loss'!C42))-N('Profit and Loss'!C43),1) -> 0 | D25: =ROUND((N('Profit and Loss'!D41)+N('Profit and Loss'!D42))-N('Profit and Loss'!D43),1) -> 0 | E25: =ROUND((N('Profit and Loss'!E41)+N('Profit and Loss'!E42))-N('Profit and Loss'!E43),1) -> 0 | F25: =ROUND((N('Profit and Loss'!F41)+N('Profit and Loss'!F42))-N('Profit and Loss'!F43),1) -> 0 | G25: =IF(AND(OR(B25="",B25=0),OR(C25="",C25=0),OR(D25="",D25=0),OR(E25="",E25=0),OR(F25="",F25=0)),"OK","CHECK") -> OK
A26: Total comprehensive income / (loss) for the year | B26: =ROUND((N('Profit and Loss'!B37)+N('Profit and Loss'!B43))-N('Profit and Loss'!B44),1) -> 0 | C26: =ROUND((N('Profit and Loss'!C37)+N('Profit and Loss'!C43))-N('Profit and Loss'!C44),1) -> 0 | D26: =ROUND((N('Profit and Loss'!D37)+N('Profit and Loss'!D43))-N('Profit and Loss'!D44),1) -> 0 | E26: =ROUND((N('Profit and Loss'!E37)+N('Profit and Loss'!E43))-N('Profit and Loss'!E44),1) -> 0 | F26: =ROUND((N('Profit and Loss'!F37)+N('Profit and Loss'!F43))-N('Profit and Loss'!F44),1) -> 0 | G26: =IF(AND(OR(B26="",B26=0),OR(C26="",C26=0),OR(D26="",D26=0),OR(E26="",E26=0),OR(F26="",F26=0)),"OK","CHECK") -> OK
A27: Statement of Cash Flows
A28: Cash flows from operating activities | B28: =ROUND((N('Cash Flows'!B9)+SUM('Cash Flows'!B11:B33))-N('Cash Flows'!B34),1) -> 0 | C28: =ROUND((N('Cash Flows'!C9)+SUM('Cash Flows'!C11:C33))-N('Cash Flows'!C34),1) -> 0 | D28: =ROUND((N('Cash Flows'!D9)+SUM('Cash Flows'!D11:D33))-N('Cash Flows'!D34),1) -> 0 | E28: =ROUND((N('Cash Flows'!E9)+SUM('Cash Flows'!E11:E33))-N('Cash Flows'!E34),1) -> 0 | F28: =ROUND((N('Cash Flows'!F9)+SUM('Cash Flows'!F11:F33))-N('Cash Flows'!F34),1) -> 0 | G28: =IF(AND(OR(B28="",B28=0),OR(C28="",C28=0),OR(D28="",D28=0),OR(E28="",E28=0),OR(F28="",F28=0)),"OK","CHECK") -> OK
A29: Net cash flows from operating activities | B29: =ROUND((N('Cash Flows'!B34)+N('Cash Flows'!B35))-N('Cash Flows'!B36),1) -> 0 | C29: =ROUND((N('Cash Flows'!C34)+N('Cash Flows'!C35))-N('Cash Flows'!C36),1) -> 0 | D29: =ROUND((N('Cash Flows'!D34)+N('Cash Flows'!D35))-N('Cash Flows'!D36),1) -> 0 | E29: =ROUND((N('Cash Flows'!E34)+N('Cash Flows'!E35))-N('Cash Flows'!E36),1) -> 0 | F29: =ROUND((N('Cash Flows'!F34)+N('Cash Flows'!F35))-N('Cash Flows'!F36),1) -> 0 | G29: =IF(AND(OR(B29="",B29=0),OR(C29="",C29=0),OR(D29="",D29=0),OR(E29="",E29=0),OR(F29="",F29=0)),"OK","CHECK") -> OK
A30: Net cash flows (used in) investing activities | B30: =ROUND((SUM('Cash Flows'!B39:B49))-N('Cash Flows'!B50),1) -> 0 | C30: =ROUND((SUM('Cash Flows'!C39:C49))-N('Cash Flows'!C50),1) -> 0 | D30: =ROUND((SUM('Cash Flows'!D39:D49))-N('Cash Flows'!D50),1) -> 0 | E30: =ROUND((SUM('Cash Flows'!E39:E49))-N('Cash Flows'!E50),1) -> 0 | F30: =ROUND((SUM('Cash Flows'!F39:F49))-N('Cash Flows'!F50),1) -> 0 | G30: =IF(AND(OR(B30="",B30=0),OR(C30="",C30=0),OR(D30="",D30=0),OR(E30="",E30=0),OR(F30="",F30=0)),"OK","CHECK") -> OK
A31: Net cash flows (used in) / generated from financing activities | B31: =ROUND((SUM('Cash Flows'!B53:B65))-N('Cash Flows'!B66),1) -> 0 | C31: =ROUND((SUM('Cash Flows'!C53:C65))-N('Cash Flows'!C66),1) -> 0 | D31: =ROUND((SUM('Cash Flows'!D53:D65))-N('Cash Flows'!D66),1) -> 0 | E31: =ROUND((SUM('Cash Flows'!E53:E65))-N('Cash Flows'!E66),1) -> 0 | F31: =ROUND((SUM('Cash Flows'!F53:F65))-N('Cash Flows'!F66),1) -> 0 | G31: =IF(AND(OR(B31="",B31=0),OR(C31="",C31=0),OR(D31="",D31=0),OR(E31="",E31=0),OR(F31="",F31=0)),"OK","CHECK") -> OK
A32: Net increase / (decrease) in cash and cash equivalents | B32: =ROUND((N('Cash Flows'!B36)+N('Cash Flows'!B50)+N('Cash Flows'!B66))-N('Cash Flows'!B68),1) -> 0 | C32: =ROUND((N('Cash Flows'!C36)+N('Cash Flows'!C50)+N('Cash Flows'!C66))-N('Cash Flows'!C68),1) -> 0 | D32: =ROUND((N('Cash Flows'!D36)+N('Cash Flows'!D50)+N('Cash Flows'!D66))-N('Cash Flows'!D68),1) -> 0 | E32: =ROUND((N('Cash Flows'!E36)+N('Cash Flows'!E50)+N('Cash Flows'!E66))-N('Cash Flows'!E68),1) -> 0 | F32: =ROUND((N('Cash Flows'!F36)+N('Cash Flows'!F50)+N('Cash Flows'!F66))-N('Cash Flows'!F68),1) -> 0 | G32: =IF(AND(OR(B32="",B32=0),OR(C32="",C32=0),OR(D32="",D32=0),OR(E32="",E32=0),OR(F32="",F32=0)),"OK","CHECK") -> OK
A33: Cash and cash equivalents at the end of the year | B33: =ROUND((N('Cash Flows'!B69)+N('Cash Flows'!B68))-N('Cash Flows'!B70),1) -> 0 | C33: =ROUND((N('Cash Flows'!C69)+N('Cash Flows'!C68))-N('Cash Flows'!C70),1) -> 0 | D33: =ROUND((N('Cash Flows'!D69)+N('Cash Flows'!D68))-N('Cash Flows'!D70),1) -> 0 | E33: =ROUND((N('Cash Flows'!E69)+N('Cash Flows'!E68))-N('Cash Flows'!E70),1) -> 0 | F33: =ROUND((N('Cash Flows'!F69)+N('Cash Flows'!F68))-N('Cash Flows'!F70),1) -> 0 | G33: =IF(AND(OR(B33="",B33=0),OR(C33="",C33=0),OR(D33="",D33=0),OR(E33="",E33=0),OR(F33="",F33=0)),"OK","CHECK") -> OK
A34: Opening cash of the year = closing cash of the previous year (FY2025-26: within half a crore, as that report rounds to whole crore) | C34: =ROUND(N('Cash Flows'!C69)-N('Cash Flows'!B70),1) -> 0 | D34: =ROUND(N('Cash Flows'!D69)-N('Cash Flows'!C70),1) -> 0 | E34: =ROUND(N('Cash Flows'!E69)-N('Cash Flows'!D70),1) -> 0 | F34: =ROUND(IF(ABS(N('Cash Flows'!F69)-N('Cash Flows'!E70))<=0.5,0,N('Cash Flows'!F69)-N('Cash Flows'!E70)),1) -> 0 | G34: =IF(AND(OR(B34="",B34=0),OR(C34="",C34=0),OR(D34="",D34=0),OR(E34="",E34=0),OR(F34="",F34=0)),"OK","CHECK") -> OK
A35: Cross-statement agreement
A36: Closing cash in Cash Flow Statement = Cash and cash equivalents on Balance Sheet | B36: =ROUND(N('Cash Flows'!B70)-N('Balance Sheet'!B25),1) -> 0 | C36: =ROUND(N('Cash Flows'!C70)-N('Balance Sheet'!C25),1) -> 0 | D36: =ROUND(N('Cash Flows'!D70)-N('Balance Sheet'!D25),1) -> 0 | E36: =ROUND(N('Cash Flows'!E70)-N('Balance Sheet'!E25),1) -> 0 | F36: =ROUND(N('Cash Flows'!F70)-N('Balance Sheet'!F25),1) -> 0 | G36: =IF(AND(OR(B36="",B36=0),OR(C36="",C36=0),OR(D36="",D36=0),OR(E36="",E36=0),OR(F36="",F36=0)),"OK","CHECK") -> OK
A37: Profit / (Loss) before tax: Cash Flow Statement = Statement of Profit and Loss | B37: =ROUND(N('Cash Flows'!B9)-N('Profit and Loss'!B33),1) -> 0 | C37: =ROUND(N('Cash Flows'!C9)-N('Profit and Loss'!C33),1) -> 0 | D37: =ROUND(N('Cash Flows'!D9)-N('Profit and Loss'!D33),1) -> 0 | E37: =ROUND(N('Cash Flows'!E9)-N('Profit and Loss'!E33),1) -> 0 | F37: =ROUND(N('Cash Flows'!F9)-N('Profit and Loss'!F33),1) -> 0 | G37: =IF(AND(OR(B37="",B37=0),OR(C37="",C37=0),OR(D37="",D37=0),OR(E37="",E37=0),OR(F37="",F37=0)),"OK","CHECK") -> OK
A38: Depreciation: Cash Flow Statement = Statement of Profit and Loss | B38: =ROUND(N('Cash Flows'!B12)-N('Profit and Loss'!B27),1) -> 0 | C38: =ROUND(N('Cash Flows'!C12)-N('Profit and Loss'!C27),1) -> 0 | D38: =ROUND(N('Cash Flows'!D12)-N('Profit and Loss'!D27),1) -> 0 | E38: =ROUND(N('Cash Flows'!E12)-N('Profit and Loss'!E27),1) -> 0 | F38: =ROUND(N('Cash Flows'!F12)-N('Profit and Loss'!F27),1) -> 0 | G38: =IF(AND(OR(B38="",B38=0),OR(C38="",C38=0),OR(D38="",D38=0),OR(E38="",E38=0),OR(F38="",F38=0)),"OK","CHECK") -> OK
A39: Amortisation: Cash Flow Statement = Statement of Profit and Loss | B39: =ROUND(N('Cash Flows'!B13)-N('Profit and Loss'!B28),1) -> 0 | C39: =ROUND(N('Cash Flows'!C13)-N('Profit and Loss'!C28),1) -> 0 | D39: =ROUND(N('Cash Flows'!D13)-N('Profit and Loss'!D28),1) -> 0 | E39: =ROUND(N('Cash Flows'!E13)-N('Profit and Loss'!E28),1) -> 0 | F39: =ROUND(N('Cash Flows'!F13)-N('Profit and Loss'!F28),1) -> 0 | G39: =IF(AND(OR(B39="",B39=0),OR(C39="",C39=0),OR(D39="",D39=0),OR(E39="",E39=0),OR(F39="",F39=0)),"OK","CHECK") -> OK
A40: Finance costs: Cash Flow Statement = Statement of Profit and Loss | B40: =ROUND(N('Cash Flows'!B20)-N('Profit and Loss'!B26),1) -> 0 | C40: =ROUND(N('Cash Flows'!C20)-N('Profit and Loss'!C26),1) -> 0 | D40: =ROUND(N('Cash Flows'!D20)-N('Profit and Loss'!D26),1) -> 0 | E40: =ROUND(N('Cash Flows'!E20)-N('Profit and Loss'!E26),1) -> 0 | F40: =ROUND(N('Cash Flows'!F20)-N('Profit and Loss'!F26),1) -> 0 | G40: =IF(AND(OR(B40="",B40=0),OR(C40="",C40=0),OR(D40="",D40=0),OR(E40="",E40=0),OR(F40="",F40=0)),"OK","CHECK") -> OK
A41: Total comprehensive income: Changes in Equity = Statement of Profit and Loss | B41: =ROUND(N('Changes in Equity'!K30)-N('Profit and Loss'!B44),1) -> 0 | C41: =ROUND(N('Changes in Equity'!K37)-N('Profit and Loss'!C44),1) -> 0 | D41: =ROUND(N('Changes in Equity'!K46)-N('Profit and Loss'!D44),1) -> 0 | E41: =ROUND(N('Changes in Equity'!K54)-N('Profit and Loss'!E44),1) -> 0 | F41: =ROUND(N('Changes in Equity'!K65)-N('Profit and Loss'!F44),1) -> 0 | G41: =IF(AND(OR(B41="",B41=0),OR(C41="",C41=0),OR(D41="",D41=0),OR(E41="",E41=0),OR(F41="",F41=0)),"OK","CHECK") -> OK
...
